Workbook

Sheet ROPO CELKEM
A1: Číslo rozp. Kapitol | B1: Název kapitoly | E1: SCHV. ROZPOČET 2024 | K1: INDEX Ø platu | L1: UPRAV. ROZPOČET 2024 | R1: SKUTEČNOST 2024 | X1: INDEX Ø platu | AA1: SCHV. ROZPOČET 2025 | AG1: INDEX Ø platu | AH1: UPRAV. ROZPOČET 2025 | AN1: SKUTEČNOST 2025 | AT1: INDEX Ø platu
C3: Rozpočtová | E3: PROSTŘEDKY NA PLATY A OPPP v Kč | F3: z toho : | H3: POČET ZAMĚSTANCŮ | I3: Ø měsíční plat v Kč | J3: Pořadí Ø měsíčního platu | K3: schv. 2017 ke schv. 2016 | L3: PROSTŘEDKY NA PLATY A OPPP v Kč | M3: z toho : | O3: POČET ZAMĚSTANCŮ | P3: Ø měsíční plat v Kč | Q3: Pořadí Ø měsíčního platu | R3: PROSTŘEDKY NA PLATY A OPPP v Kč | S3: z toho : | U3: POČET ZAMĚSTANCŮ | V3: Ø měsíční plat v Kč | W3: Pořadí Ø měsíčního platu | X3: skut. 2017 k uprav. rozp. 2017 | Y3: skut. 2017 ke skut. 2016 | AA3: PROSTŘEDKY NA PLATY A OPPP v Kč | AB3: z toho : | AD3: POČET ZAMĚSTANCŮ | AE3: Ø měsíční plat v Kč | AF3: Pořadí Ø měsíčního platu | AG3: schv. 2017 ke schv. 2016 | AH3: PROSTŘEDKY NA PLATY A OPPP v Kč | AI3: z toho : | AK3: POČET ZAMĚSTANCŮ | AL3: Ø měsíční plat v Kč | AM3: Pořadí Ø měsíčního platu | AN3: PROSTŘEDKY NA PLATY A OPPP v Kč | AO3: z toho : | AQ3: POČET ZAMĚSTANCŮ | AR3: Ø měsíční plat v Kč | AS3: Pořadí Ø měsíčního platu | AT3: skut. 2017 k uprav. rozp. 2017 | AU3: skut. 2017 ke skut. 2016
C4: kapitola | F4: OPPP v Kč | G4: PROSTŘEDKY NA PLATY | M4: OPPP v Kč | N4: PROSTŘEDKY NA PLATY | S4: OPPP v Kč | T4: PROSTŘEDKY NA PLATY | AB4: OPPP v Kč | AC4: PROSTŘEDKY NA PLATY | AI4: OPPP v Kč | AJ4: PROSTŘEDKY NA PLATY | AO4: OPPP v Kč | AP4: PROSTŘEDKY NA PLATY
A6: 301 | B6: KPR | C6: Kancelář prezidenta | E6: 206171801 | F6: 9267356 | G6: 196904445 | H6: 420 | I6: 39068 | J6: =RANK(I6,I$6:I$49,0) -> 40 | L6: 206171801 | M6: 9267356 | N6: 196904445 | O6: 420 | P6: 39068 | Q6: =RANK(P6,P$6:P$49,0) -> 41 | R6: 260753498 | S6: 8250553 | T6: 252502945 | U6: 403.07 | V6: 52204 | W6: =RANK(V6,V$6:V$49,0) -> 23 | X6: 115.97249 | Y6: 102.40099 | AA6: 249138546 | AB6: 9828956 | AC6: 239309590 | AD6: 420 | AE6: 47482 | AF6: =RANK(AE6,AE$6:AE$49,0) -> 32 | AH6: 249138546 | AI6: 9828956 | AJ6: 239309590 | AK6: 420 | AL6: 47482 | AM6: =RANK(AL6,AL$6:AL$49,0) -> 32 | AN6: 283004024 | AO6: 8388875 | AP6: 274615149 | AQ6: 407.5 | AR6: 56159 | AS6: =RANK(AR6,AR$6:AR$49,0) -> 21
A7: 302 | B7: Kparl | C7: Parlament | E7: 552557633 | F7: 320950304 | G7: 231607329 | H7: 360 | I7: 53613 | J7: =RANK(I7,I$6:I$49,0) -> 10 | L7: 543589023 | M7: 311981694 | N7: 231607329 | O7: 360 | P7: 53613 | Q7: =RANK(P7,P$6:P$49,0) -> 10 | R7: 542209624 | S7: 295407844 | T7: 246801780 | U7: 350.18 | V7: 58732 | W7: =RANK(V7,V$6:V$49,0) -> 8 | X7: 110.61763 | Y7: 106.0094 | AA7: 608771243 | AB7: 365583548 | AC7: 243187695 | AD7: 360 | AE7: 56293 | AF7: =RANK(AE7,AE$6:AE$49,0) -> 9 | AH7: 608771243 | AI7: 350583548 | AJ7: 258187695 | AK7: 360 | AL7: 59766 | AM7: =RANK(AL7,AL$6:AL$49,0) -> 5 | AN7: 588409387 | AO7: 315948518 | AP7: 272460869 | AQ7: 353.85 | AR7: 64166 | AS7: =RANK(AR7,AR$6:AR$49,0) -> 9
A8: 303 | B8: Ksen | C8: Kancelář Senátu | E8: 269729032 | F8: 147988022 | G8: 121741010 | H8: 203 | I8: 49976 | J8: =RANK(I8,I$6:I$49,0) -> 20 | L8: 269729032 | M8: 147988022 | N8: 121741010 | O8: 203 | P8: 49976 | Q8: =RANK(P8,P$6:P$49,0) -> 21 | R8: 257044581 | S8: 129848776 | T8: 127195805 | U8: 192.12 | V8: 55172 | W8: =RANK(V8,V$6:V$49,0) -> 17 | X8: 111.5062 | Y8: 105.97116 | AA8: 285727130 | AB8: 149499069 | AC8: 136228061 | AD8: 203 | AE8: 55923 | AF8: =RANK(AE8,AE$6:AE$49,0) -> 13 | AH8: 285727130 | AI8: 149499069 | AJ8: 136228061 | AK8: 203 | AL8: 55923 | AM8: =RANK(AL8,AL$6:AL$49,0) -> 15 | AN8: 288969406 | AO8: 148353620 | AP8: 140615786 | AQ8: 191.55 | AR8: 61175 | AS8: =RANK(AR8,AR$6:AR$49,0) -> 11
A9: 304 | B9: ÚV | C9: Úřad vlády | E9: 465704149 | F9: 75110024 | G9: 390594125 | H9: 589 | I9: 55262 | J9: =RANK(I9,I$6:I$49,0) -> 7 | L9: 517187881 | M9: 85705212 | N9: 431482669 | O9: 583.79 | P9: 61592 | Q9: =RANK(P9,P$6:P$49,0) -> 4 | R9: 512218563 | S9: 92244335 | T9: 419974228 | U9: 549.44 | V9: 63697 | W9: =RANK(V9,V$6:V$49,0) -> 4 | X9: 104.23737 | Y9: 104.32086 | AA9: 504163458 | AB9: 91738048 | AC9: 412425410 | AD9: 596.5 | AE9: 57617 | AF9: =RANK(AE9,AE$6:AE$49,0) -> 8 | AH9: 507542726 | AI9: 89538748 | AJ9: 418003978 | AK9: 584.25 | AL9: 59621 | AM9: =RANK(AL9,AL$6:AL$49,0) -> 6 | AN9: 518695257 | AO9: 79745871 | AP9: 438949386 | AQ9: 540.19 | AR9: 67715 | AS9: =RANK(AR9,AR$6:AR$49,0) -> 4
A10: 306 | B10: MZV | C10: Ministerstvo zahraničních věcí | E10: 1162402381 | F10: 9538950 | G10: 1152863431 | H10: 2151 | I10: 44664 | J10: =RANK(I10,I$6:I$49,0) -> 28 | L10: 1162198781 | M10: 9538950 | N10: 1152659831 | O10: 2150.66 | P10: 44663 | Q10: =RANK(P10,P$6:P$49,0) -> 32 | R10: 1150819473 | S10: 10374940 | T10: 1140444533 | U10: 1936.4 | V10: 49079 | W10: =RANK(V10,V$6:V$49,0) -> 28 | X10: 109.7802 | Y10: 107.73189 | AA10: 1218786299 | AB10: 9859350 | AC10: 1208926949 | AD10: 2149 | AE10: 46879 | AF10: =RANK(AE10,AE$6:AE$49,0) -> 34 | AH10: 1215213280 | AI10: 12322846 | AJ10: 1202890434 | AK10: 2149.58 | AL10: 46633 | AM10: =RANK(AL10,AL$6:AL$49,0) -> 34 | AN10: 1.2037275e+09 | AO10: 9684006.4 | AP10: 1194043491 | AQ10: 1945.75 | AR10: 51139 | AS10: =RANK(AR10,AR$6:AR$49,0) -> 33
A11: 307 | B11: MO | C11: Ministerstvo obrany | E11: 21953327619 | F11: 1488540656 | G11: 20464786963 | H11: 38691 | I11: 44077 | J11: =RANK(I11,I$6:I$49,0) -> 31 | L11: 22471921037 | M11: 1576083689 | N11: 20895837348 | O11: 38691 | P11: 45006 | Q11: =RANK(P11,P$6:P$49,0) -> 31 | R11: 2.1776562e+10 | S11: 1.5317053e+09 | T11: 2.0244857e+10 | U11: 36749.73 | V11: 45907 | W11: =RANK(V11,V$6:V$49,0) -> 35 | X11: 102.38595 | Y11: 107.16422 | AA11: 24013544242 | AB11: 1486646458 | AC11: 22526897784 | AD11: 39881 | AE11: 47071 | AF11: =RANK(AE11,AE$6:AE$49,0) -> 33 | AH11: 23395303305 | AI11: 1491270608 | AJ11: 21904032697 | AK11: 39881 | AL11: 45770 | AM11: =RANK(AL11,AL$6:AL$49,0) -> 36 | AN11: 2.3614967e+10 | AO11: 1.5300254e+09 | AP11: 2.2084941e+10 | AQ11: 37394.52 | AR11: 49216 | AS11: =RANK(AR11,AR$6:AR$49,0) -> 36
A12: 308 | B12: NBÚ | C12: Národní bezpečnostní úřad | E12: 169118073 | F12: 1420438 | G12: 167697635 | H12: 262 | I12: 53339 | J12: =RANK(I12,I$6:I$49,0) -> 11 | L12: 171118073 | M12: 1420438 | N12: 169697635 | O12: 262 | P12: 53975 | Q12: =RANK(P12,P$6:P$49,0) -> 9 | R12: 163305774 | S12: 1287300 | T12: 162018474 | U12: 235.18 | V12: 57409 | W12: =RANK(V12,V$6:V$49,0) -> 11 | X12: 114.17636 | Y12: 107.49139 | AA12: 177502955 | AB12: 1420438 | AC12: 176082517 | AD12: 262 | AE12: 56006 | AF12: =RANK(AE12,AE$6:AE$49,0) -> 11 | AH12: 184411290 | AI12: 1420438 | AJ12: 182990852 | AK12: 262 | AL12: 58203 | AM12: =RANK(AL12,AL$6:AL$49,0) -> 8 | AN12: 182091638 | AO12: 2626566 | AP12: 179465072 | AQ12: 232.85 | AR12: 64228 | AS12: =RANK(AR12,AR$6:AR$49,0) -> 8
A13: 309 | B13: KVOP | C13: Kancelář veřejného ochránce práv | E13: 91264225 | F13: 7993580 | G13: 83270645 | H13: 154 | I13: 45060 | J13: =RANK(I13,I$6:I$49,0) -> 27 | L13: 94264225 | M13: 7993580 | N13: 86270645 | O13: 154 | P13: 46683 | Q13: =RANK(P13,P$6:P$49,0) -> 25 | R13: 95891502 | S13: 9088750 | T13: 86802752 | U13: 153.11 | V13: 47244 | W13: =RANK(V13,V$6:V$49,0) -> 34 | X13: 100.58525 | Y13: 104.34503 | AA13: 107206357 | AB13: 12010580 | AC13: 95195777 | AD13: 154 | AE13: 51513 | AF13: =RANK(AE13,AE$6:AE$49,0) -> 24 | AH13: 110204414 | AI13: 12010580 | AJ13: 98193834 | AK13: 158.85 | AL13: 51513 | AM13: =RANK(AL13,AL$6:AL$49,0) -> 23 | AN13: 1.0715732e+08 | AO13: 9284877 | AP13: 97872447 | AQ13: 156.77 | AR13: 52025 | AS13: =RANK(AR13,AR$6:AR$49,0) -> 31
A14: 312 | B14: MF | C14: Ministerstvo financí | E14: 13038946442 | F14: 57330478 | G14: 12981615964 | H14: 23458 | I14: 46117 | J14: =RANK(I14,I$6:I$49,0) -> 26 | L14: 13049114063 | M14: 58254903 | N14: 12990859160 | O14: 23456.87 | P14: 46152 | Q14: =RANK(P14,P$6:P$49,0) -> 28 | R14: 1.273951e+10 | S14: 76307371 | T14: 1.2663203e+10 | U14: 21604.61 | V14: 48845 | W14: =RANK(V14,V$6:V$49,0) -> 30 | X14: 108.22808 | Y14: 113.69855 | AA14: 13698338262 | AB14: 57080922 | AC14: 13641257340 | AD14: 23308.667 | AE14: 48770 | AF14: =RANK(AE14,AE$6:AE$49,0) -> 30 | AH14: 13312889256 | AI14: 61477124 | AJ14: 13251412132 | AK14: 23323 | AL14: 47347 | AM14: =RANK(AL14,AL$6:AL$49,0) -> 33 | AN14: 1.3228378e+10 | AO14: 47861289 | AP14: 1.3180517e+10 | AQ14: 21323.57 | AR14: 51510 | AS14: =RANK(AR14,AR$6:AR$49,0) -> 32
A15: 313 | B15: MPSV | C15: Ministerstvo práce a sociálních věcí | E15: 9333365843 | F15: 53402724 | G15: 9279963119 | H15: 22717.55 | I15: 34041 | J15: =RANK(I15,I$6:I$49,0) -> 44 | L15: 10696626917 | M15: 253439469 | N15: 10443187448 | O15: 21889.25 | P15: 39758 | Q15: =RANK(P15,P$6:P$49,0) -> 40 | R15: 1.068464e+10 | S15: 239195812 | T15: 1.0445445e+10 | U15: 20942.54 | V15: 41564 | W15: =RANK(V15,V$6:V$49,0) -> 41 | X15: 103.65293 | Y15: 107.45682 | AA15: 10077513117 | AB15: 102266077 | AC15: 9975247040 | AD15: 22100 | AE15: 37614 | AF15: =RANK(AE15,AE$6:AE$49,0) -> 43 | AH15: 10983290523 | AI15: 122058620 | AJ15: 10861231903 | AK15: 21919.2 | AL15: 41293 | AM15: =RANK(AL15,AL$6:AL$49,0) -> 42 | AN15: 1.0864002e+10 | AO15: 121391225 | AP15: 1.0742611e+10 | AQ15: 20511.99 | AR15: 43644 | AS15: =RANK(AR15,AR$6:AR$49,0) -> 42
A16: 314 | B16: MV | C16: Ministerstvo vnitra | E16: 41411281211 | F16: 379056240 | G16: 41032224971 | H16: 73882.83 | I16: 46281 | J16: =RANK(I16,I$6:I$49,0) -> 25 | L16: 42066145769 | M16: 597912182 | N16: 41468233587 | O16: 74165.57 | P16: 46594 | Q16: =RANK(P16,P$6:P$49,0) -> 26 | R16: 4.2140096e+10 | S16: 6.282509e+08 | T16: 4.1511845e+10 | U16: 67090.19 | V16: 51562 | W16: =RANK(V16,V$6:V$49,0) -> 25 | X16: 104.15274 | Y16: 109.3147 | AA16: 44532705533 | AB16: 471077671 | AC16: 44061627862 | AD16: 74119.88 | AE16: 49539 | AF16: =RANK(AE16,AE$6:AE$49,0) -> 26 | AH16: 45364390973 | AI16: 591906342 | AJ16: 44772484631 | AK16: 74123.76 | AL16: 50335 | AM16: =RANK(AL16,AL$6:AL$49,0) -> 26 | AN16: 4.5334838e+10 | AO16: 6.7591762e+08 | AP16: 4.4658921e+10 | AQ16: 67216.04 | AR16: 55367 | AS16: =RANK(AR16,AR$6:AR$49,0) -> 23
A17: 315 | B17: MŽP | C17: Ministerstvo životního prostředí | E17: 1944706412 | F17: 62555590 | G17: 1882150822 | H17: 3556.53 | I17: 44101 | J17: =RANK(I17,I$6:I$49,0) -> 30 | L17: 2100034101 | M17: 95126225 | N17: 2004907876 | O17: 3648.14 | P17: 45797 | Q17: =RANK(P17,P$6:P$49,0) -> 30 | R17: 2.1477277e+09 | S17: 91307105 | T17: 2056420593 | U17: 3501.95 | V17: 48935 | W17: =RANK(V17,V$6:V$49,0) -> 29 | X17: 103.33994 | Y17: 108.21418 | AA17: 2159699558 | AB17: 67270455 | AC17: 2092429103 | AD17: 3660.61 | AE17: 47634 | AF17: =RANK(AE17,AE$6:AE$49,0) -> 31 | AH17: 2196057349 | AI17: 80460850 | AJ17: 2115596499 | AK17: 3700.52 | AL17: 47642 | AM17: =RANK(AL17,AL$6:AL$49,0) -> 31 | AN17: 2.3574031e+09 | AO17: 99208465 | AP17: 2.2581947e+09 | AQ17: 3597.73 | AR17: 52306 | AS17: =RANK(AR17,AR$6:AR$49,0) -> 29
... A39: 362 | B39: NSA | C39: Národní sportovní agentura | E39: 50394848 | F39: 8170182 | G39: 42224666 | H39: 83 | I39: 42394 | J39: =RANK(I39,I$6:I$49,0) -> 36 | L39: 61290942 | M39: 8170182 | N39: 53120760 | O39: 84.5 | P39: 52387 | Q39: =RANK(P39,P$6:P$49,0) -> 15 | R39: 62415320 | S39: 8825455 | T39: 53589865 | U39: 77.5 | V39: 57624 | W39: =RANK(V39,V$6:V$49,0) -> 10 | X39: 0 | Y39: 0 | AA39: 64665780 | AB39: 8888982 | AC39: 55776798 | AD39: 86 | AE39: 54047 | AF39: =RANK(AE39,AE$6:AE$49,0) -> 17 | AH39: 67560781 | AI39: 8888982 | AJ39: 58671799 | AK39: 86 | AL39: 56853 | AM39: =RANK(AL39,AL$6:AL$49,0) -> 12 | AN39: 64594397 | AO39: 9710213 | AP39: 54884184 | AQ39: 78.47 | AR39: 58286 | AS39: =RANK(AR39,AR$6:AR$49,0) -> 17
A40: 364 | B40: DIA | E40: 206924933 | F40: 5033240 | G40: 201891693 | H40: 207.5 | I40: 81081 | L40: 324983930 | M40: 27595670 | N40: 297388260 | O40: 324.67 | P40: 76331 | R40: 205453831 | S40: 20100351 | T40: 185353480 | U40: 221.97 | V40: 69587 | AA40: 376169213 | AB40: 75043805 | AC40: 301125408 | AD40: 337 | AE40: 74462 | AF40: =RANK(AE40,AE$6:AE$49,0) -> 2 | AH40: 390753807 | AI40: 82921805 | AJ40: 307832002 | AK40: 343.83 | AL40: 74609 | AM40: =RANK(AL40,AL$6:AL$49,0) -> 2 | AN40: 292930858 | AO40: 32743819 | AP40: 260187039 | AQ40: 280.89 | AR40: 77191
A41: 371 | B41: ÚDHPS | C41: Úřad pro dohled nad hospodařením politických stran a politických hnutí | E41: 16986049 | F41: 700000 | G41: 16286049 | H41: 19 | I41: 71430 | J41: =RANK(I41,I$6:I$49,0) -> 2 | L41: 16986049 | M41: 700000 | N41: 16286049 | O41: 19 | P41: 71430 | Q41: =RANK(P41,P$6:P$49,0) -> 2 | R41: 15266854 | S41: 37875 | T41: 15228979 | U41: 18.4 | V41: 68972 | W41: =RANK(V41,V$6:V$49,0) -> 3 | X41: 127.00461 | Y41: 0 | AA41: 19462623 | AB41: 700000 | AC41: 18762623 | AD41: 20 | AE41: 78178 | AF41: =RANK(AE41,AE$6:AE$49,0) -> 1 | AH41: 19462623 | AI41: 700000 | AJ41: 18762623 | AK41: 20 | AL41: 78178 | AM41: =RANK(AL41,AL$6:AL$49,0) -> 1 | AN41: 18094945 | AO41: 28125 | AP41: 18066820 | AQ41: 19.53 | AR41: 77090 | AS41: =RANK(AR41,AR$6:AR$49,0) -> 3
A42: 372 | B42: RRTV | C42: Rada pro rozhlasové a televizní vysílání | E42: 43284149 | F42: 17917296 | G42: 25366853 | H42: 48 | I42: 44040 | J42: =RANK(I42,I$6:I$49,0) -> 32 | L42: 42703882 | M42: 17337029 | N42: 25366853 | O42: 48 | P42: 44040 | Q42: =RANK(P42,P$6:P$49,0) -> 34 | R42: 41385445 | S42: 17272632 | T42: 24112813 | U42: 44 | V42: 45668 | W42: =RANK(V42,V$6:V$49,0) -> 36 | X42: 109.8789 | Y42: 107.11182 | AA42: 48661592 | AB42: 20188896 | AC42: 28472696 | AD42: 48 | AE42: 49432 | AF42: =RANK(AE42,AE$6:AE$49,0) -> 27 | AH42: 48661592 | AI42: 20188896 | AJ42: 28472696 | AK42: 48 | AL42: 49432 | AM42: =RANK(AL42,AL$6:AL$49,0) -> 27 | AN42: 46443629 | AO42: 19556123 | AP42: 26887506 | AQ42: 43 | AR42: 52108 | AS42: =RANK(AR42,AR$6:AR$49,0) -> 30
A43: 373 | B43: ÚPDI | E43: 15140797 | F43: 300000 | G43: 14840797 | H43: 23 | I43: 53771 | J43: =RANK(I43,I$6:I$49,0) -> 9 | X43: 103.71916 | Y43: 0
A44: 374 | B44: SSHR | C44: Správa státních hmotných rezerv | E44: 205656880 | F44: 1357529 | G44: 204299351 | H44: 416 | I44: 40925 | J44: =RANK(I44,I$6:I$49,0) -> 37 | L44: 209421880 | M44: 1357529 | N44: 208064351 | O44: 416 | P44: 41680 | Q44: =RANK(P44,P$6:P$49,0) -> 38 | R44: 205569155 | S44: 1265364 | T44: 204303791 | U44: 373.85 | V44: 45540 | W44: =RANK(V44,V$6:V$49,0) -> 37 | X44: 105.08833 | Y44: 105.5875 | AA44: 215014318 | AB44: 1357529 | AC44: 213656789 | AD44: 416 | AE44: 42800 | AF44: =RANK(AE44,AE$6:AE$49,0) -> 39 | AH44: 215014318 | AI44: 1357529 | AJ44: 213656789 | AK44: 416 | AL44: 42800 | AM44: =RANK(AL44,AL$6:AL$49,0) -> 39 | AN44: 218663897 | AO44: 1847377 | AP44: 216816520 | AQ44: 376.14 | AR44: 48035 | AS44: =RANK(AR44,AR$6:AR$49,0) -> 37
A45: 375 | B45: SÚJB | C45: Státní úřad pro jadernou bezpečnost | E45: 152152559 | F45: 2000700 | G45: 150151859 | H45: 218 | I45: 57397 | J45: =RANK(I45,I$6:I$49,0) -> 4 | L45: 152152559 | M45: 2000700 | N45: 150151859 | O45: 218 | P45: 57397 | Q45: =RANK(P45,P$6:P$49,0) -> 5 | R45: 150907206 | S45: 2792212 | T45: 148114994 | U45: 196.82 | V45: 62712 | W45: =RANK(V45,V$6:V$49,0) -> 5 | X45: 104.95619 | Y45: 108.30305 | AA45: 170611915 | AB45: 2000700 | AC45: 168611215 | AD45: 237 | AE45: 59287 | AF45: =RANK(AE45,AE$6:AE$49,0) -> 5 | AH45: 170611915 | AI45: 2000700 | AJ45: 168611215 | AK45: 237 | AL45: 59287 | AM45: =RANK(AL45,AL$6:AL$49,0) -> 7 | AN45: 165650329 | AO45: 3194379 | AP45: 162455950 | AQ45: 204.75 | AR45: 66120 | AS45: =RANK(AR45,AR$6:AR$49,0) -> 6
A46: 376 | B46: GIBS | C46: Generální inspekce bezpečnostních sborů | E46: 269397297 | F46: 2079040 | G46: 267318257 | H46: 333 | I46: 66896 | J46: =RANK(I46,I$6:I$49,0) -> 3 | L46: 269397297 | M46: 2079040 | N46: 267318257 | O46: 333 | P46: 66896 | Q46: =RANK(P46,P$6:P$49,0) -> 3 | R46: 2.6192174e+08 | S46: 2188741 | T46: 2.59733e+08 | U46: 297.67 | V46: 72713 | W46: =RANK(V46,V$6:V$49,0) -> 1 | X46: 111.29527 | Y46: 125.59838 | AA46: 282763210 | AB46: 2079040 | AC46: 280684170 | AD46: 333 | AE46: 70241 | AF46: =RANK(AE46,AE$6:AE$49,0) -> 3 | AH46: 287155210 | AI46: 2079040 | AJ46: 285076170 | AK46: 333 | AL46: 71340 | AM46: =RANK(AL46,AL$6:AL$49,0) -> 3 | AN46: 277436787 | AO46: 1882911 | AP46: 275553876 | AQ46: 296.26 | AR46: 77509 | AS46: =RANK(AR46,AR$6:AR$49,0) -> 1
A47: 377 | B47: TAČR | C47: Technologická agentura ČR | E47: 94505349 | F47: 6573835 | G47: 87931514 | H47: 147.8 | I47: 49578 | J47: =RANK(I47,I$6:I$49,0) -> 21 | L47: 95770494 | M47: 7608980 | N47: 88161514 | O47: 148.18 | P47: 49580 | Q47: =RANK(P47,P$6:P$49,0) -> 22 | R47: 97273820 | S47: 6438206 | T47: 90835614 | U47: 146.13 | V47: 51801 | W47: =RANK(V47,V$6:V$49,0) -> 24 | X47: 107.43837 | Y47: 104.93751 | AA47: 98095468 | AB47: 9523835 | AC47: 88571633 | AD47: 142.27 | AE47: 51880 | AF47: =RANK(AE47,AE$6:AE$49,0) -> 22 | AH47: 102280425 | AI47: 9803835 | AJ47: 92476590 | AK47: 149.1 | AL47: 51686 | AM47: =RANK(AL47,AL$6:AL$49,0) -> 22 | AN47: 103230528 | AO47: 8010310 | AP47: 95220218 | AQ47: 144.26 | AR47: 55005 | AS47: =RANK(AR47,AR$6:AR$49,0) -> 25
A48: 378 | B48: NÚKIB | C48: Národní úřad pro kybernetickou a informační bezpečnost | E48: 239467965 | F48: 803648 | G48: 238664317 | H48: 373 | I48: 53321 | J48: =RANK(I48,I$6:I$49,0) -> 12 | L48: 239687745 | M48: 803648 | N48: 238884097 | O48: 373 | P48: 53370 | Q48: =RANK(P48,P$6:P$49,0) -> 11 | R48: 239020211 | S48: 1894625 | T48: 237125586 | U48: 357.23 | V48: 55316 | W48: =RANK(V48,V$6:V$49,0) -> 15 | X48: 97.656313 | Y48: 0 | AA48: 259183747 | AB48: 803648 | AC48: 258380099 | AD48: 385 | AE48: 55926 | AF48: =RANK(AE48,AE$6:AE$49,0) -> 12 | AH48: 261641226 | AI48: 941502 | AJ48: 260699724 | AK48: 385.17 | AL48: 56404 | AM48: =RANK(AL48,AL$6:AL$49,0) -> 14 | AN48: 259017236 | AO48: 3805621 | AP48: 255211615 | AQ48: 364.76 | AR48: 58306 | AS48: =RANK(AR48,AR$6:AR$49,0) -> 16
A49: 381 | B49: NKÚ | C49: Nejvyšší kontrolní úřad | E49: 366875024 | F49: 32988794 | G49: 333886230 | H49: 485 | I49: 57369 | J49: =RANK(I49,I$6:I$49,0) -> 5 | L49: 366875024 | M49: 32988794 | N49: 333886230 | O49: 485 | P49: 57369 | Q49: =RANK(P49,P$6:P$49,0) -> 6 | R49: 352532243 | S49: 31009532 | T49: 3.2152271e+08 | U49: 433.12 | V49: 61862 | W49: =RANK(V49,V$6:V$49,0) -> 6 | X49: 108.47367 | Y49: 106.59508 | AA49: 387824536 | AB49: 37243994 | AC49: 350580542 | AD49: 475 | AE49: 61505 | AF49: =RANK(AE49,AE$6:AE$49,0) -> 4 | AH49: 387824536 | AI49: 37243994 | AJ49: 350580542 | AK49: 475 | AL49: 61505 | AM49: =RANK(AL49,AL$6:AL$49,0) -> 4 | AN49: 384145688 | AO49: 33481326 | AP49: 350664362 | AQ49: 436.13 | AR49: 67003 | AS49: =RANK(AR49,AR$6:AR$49,0) -> 5
A50: RO CELKEM
C51: C E L K E M | E51: =SUM(E6:E49) -> 266566761782 | F51: =SUM(F6:F49) -> 10877166562 | G51: =SUM(G6:G49) -> 255689595220 | H51: =SUM(H6:H49) -> 487591.14 | I51: =G51/H51/12 -> 43699.453 | J51: - | L51: =SUM(L6:L49) -> 274022930491 | M51: =SUM(M6:M49) -> 12164612882 | N51: =SUM(N6:N49) -> 261858317609 | O51: =SUM(O6:O49) -> 496370.78 | P51: =N51/O51/12 -> 43962.15 | Q51: - | R51: =SUM(R6:R49) -> 2.7855964e+11 | S51: =SUM(S6:S49) -> 1.3789195e+10 | T51: =SUM(T6:T49) -> 2.6477044e+11 | U51: =SUM(U6:U49) -> 487078.23 | V51: =T51/U51/12 -> 45299.096 | W51: - | X51: 105.05603 | Y51: 109.02711 | AA51: =SUM(AA6:AA49) -> 286822781187 | AB51: =SUM(AB6:AB49) -> 11805231248 | AC51: =SUM(AC6:AC49) -> 275017549939 | AD51: =SUM(AD6:AD49) -> 488960.52 | AE51: =IF(AD51=0,0,ROUND(AC51/AD51/12,0)) -> 46871 | AF51: - | AH51: =SUM(AH6:AH49) -> 292626094751 | AI51: =SUM(AI6:AI49) -> 12572815043 | AJ51: =SUM(AJ6:AJ49) -> 280053279708 | AK51: =SUM(AK6:AK49) -> 500544.44 | AL51: =IF(AK51=0,0,ROUND(AJ51/AK51/12,0)) -> 46625 | AM51: - | AN51: =SUM(AN6:AN49) -> 2.9851541e+11 | AO51: =SUM(AO6:AO49) -> 1.4351298e+10 | AP51: =SUM(AP6:AP49) -> 2.8416411e+11 | AQ51: =SUM(AQ6:AQ49) -> 490977.41 | AR51: =IF(AQ51=0,0,ROUND(AP51/AQ51/12,0)) -> 48231 | AS51: -
E54: =E51=SUMAR!E14 -> TRUE | F54: =F51=SUMAR!F14 -> TRUE | G54: =G51=SUMAR!G14 -> TRUE | H54: =H51=SUMAR!H14 -> TRUE | I54: =I51=SUMAR!I14 -> TRUE | L54: =L51=SUMAR!L14 -> TRUE | M54: =M51=SUMAR!M14 -> TRUE | N54: =N51=SUMAR!N14 -> TRUE | O54: =O51=SUMAR!O14 -> TRUE | P54: =P51=SUMAR!P14 -> TRUE | R54: =R51=SUMAR!R14 -> TRUE | S54: =S51=SUMAR!S14 -> TRUE | T54: =T51=SUMAR!T14 -> TRUE | U54: =U51=SUMAR!U14 -> TRUE | V54: =V51=SUMAR!V14 -> TRUE | AA54: =AA51=SUMAR!AA14 -> TRUE | AB54: =AB51=SUMAR!AB14 -> TRUE | AC54: =AC51=SUMAR!AC14 -> TRUE | AD54: =AD51=SUMAR!AD14 -> TRUE | AE54: =AE51=SUMAR!AE14 -> TRUE | AH54: =AH51=SUMAR!AH14 -> TRUE | AI54: =AI51=SUMAR!AI14 -> TRUE | AJ54: =AJ51=SUMAR!AJ14 -> TRUE | AK54: =AK51=SUMAR!AK14 -> TRUE | AL54: =AL51=SUMAR!AL14 -> TRUE | AN54: =AN51=SUMAR!AN14 -> TRUE | AO54: =AO51=SUMAR!AO14 -> TRUE | AP54: =AP51=SUMAR!AP14 -> TRUE | AQ54: =AQ51=SUMAR!AQ14 -> TRUE | AR54: =AR51=SUMAR!AR14 -> TRUE

Sheet OSS (RO)
A1: Číslo rozp. Kapitol | B1: Název kapitoly | E1: SCHV. ROZPOČET 2013 | K1: INDEX Ø platu | L1: UPRAV. ROZPOČET 2013 | R1: SKUTEČNOST 2013 | X1: INDEX Ø platu | AA1: SCHV. ROZPOČET 2014 | AG1: INDEX Ø platu | AH1: UPRAV. ROZPOČET 2014 | AN1: SKUTEČNOST 2014 | AT1: INDEX Ø platu | AW1: SCHV. ROZPOČET 2015 | BC1: INDEX Ø platu | BD1: UPRAV. ROZPOČET 2015 | BJ1: SKUTEČNOST 2015 | BP1: INDEX Ø platu | BS1: SCHV. ROZPOČET 2016 | BY1: INDEX Ø platu | BZ1: UPRAV. ROZPOČET 2016 | CF1: SKUTEČNOST 2016 | CL1: INDEX Ø platu | CO1: SCHV. ROZPOČET 2017 | CU1: INDEX Ø platu | CV1: UPRAV. ROZPOČET 2017 | DB1: SKUTEČNOST 2017 | DH1: INDEX Ø platu | DK1: SCHV. ROZPOČET 2018 | DQ1: INDEX Ø platu | DR1: UPRAV. ROZPOČET 2018 | DX1: SKUTEČNOST 2018 | ED1: INDEX Ø platu | EG1: SCHV. ROZPOČET 2019 | EM1: INDEX Ø platu | EN1: UPRAV. ROZPOČET 2019 | ET1: SKUTEČNOST 2019 | EZ1: INDEX Ø platu | FC1: SCHV. ROZPOČET 2020 | FI1: INDEX Ø platu | FJ1: UPRAV. ROZPOČET 2020 | FP1: SKUTEČNOST 2020 | FV1: INDEX Ø platu | FY1: SCHV. ROZPOČET 2024 | GE1: INDEX Ø platu | GF1: UPRAV. ROZPOČET 2024 | GL1: SKUTEČNOST 2024 | GR1: INDEX Ø platu | GU1: SCHV. ROZPOČET 2025 | HA1: INDEX Ø platu | HB1: UPRAV. ROZPOČET 2025 | HH1: SKUTEČNOST 2025 | HN1: INDEX Ø platu
C3: Rozpočtová | E3: PROSTŘEDKY NA PLATY A OPPP v Kč | F3: z toho : | H3: POČET ZAMĚSTANCŮ | I3: Ø měsíční plat v Kč | J3: Pořadí Ø měsíčního platu | K3: schv. 2013 ke schv. 2012 | L3: PROSTŘEDKY NA PLATY A OPPP v Kč | M3: z toho : | O3: POČET ZAMĚSTANCŮ | P3: Ø měsíční plat v Kč | Q3: Pořadí Ø měsíčního platu | R3: PROSTŘEDKY NA PLATY A OPPP v Kč | S3: z toho : | U3: POČET ZAMĚSTANCŮ | V3: Ø měsíční plat v Kč | W3: Pořadí Ø měsíčního platu | X3: skut. 2013 k uprav. rozp. 2013 | Y3: skut. 2013 ke skut. 2012 | AA3: PROSTŘEDKY NA PLATY A OPPP v Kč | AB3: z toho : | AD3: POČET ZAMĚSTANCŮ | AE3: Ø měsíční plat v Kč | AF3: Pořadí Ø měsíčního platu | AG3: schv. 2014 ke schv. 2013 | AH3: PROSTŘEDKY NA PLATY A OPPP v Kč | AI3: z toho : | AK3: POČET ZAMĚSTANCŮ | AL3: Ø měsíční plat v Kč | AM3: Pořadí Ø měsíčního platu | AN3: PROSTŘEDKY NA PLATY A OPPP v Kč | AO3: z toho : | AQ3: POČET ZAMĚSTANCŮ | AR3: Ø měsíční plat v Kč | AS3: Pořadí Ø měsíčního platu | AT3: skut. 2014 k uprav. rozp. 2014 | AU3: skut. 2014 ke skut. 2013 | AW3: PROSTŘEDKY NA PLATY A OPPP v Kč | AX3: z toho : | AZ3: POČET ZAMĚSTANCŮ | BA3: Ø měsíční plat v Kč | BB3: Pořadí Ø měsíčního platu | BC3: schv. 2015 ke schv. 2014 | BD3: PROSTŘEDKY NA PLATY A OPPP v Kč | BE3: z toho : | BG3: POČET ZAMĚSTANCŮ | BH3: Ø měsíční plat v Kč | BI3: Pořadí Ø měsíčního platu | BJ3: PROSTŘEDKY NA PLATY A OPPP v Kč | BK3: z toho : | BM3: POČET ZAMĚSTANCŮ | BN3: Ø měsíční plat v Kč | BO3: Pořadí Ø měsíčního platu | BP3: skut. 2015 k uprav. rozp. 2015 | BQ3: skut. 2015 ke skut. 2014 | BS3: PROSTŘEDKY NA PLATY A OPPP v Kč | BT3: z toho : | BV3: POČET ZAMĚSTANCŮ | BW3: Ø měsíční plat v Kč | BX3: Pořadí Ø měsíčního platu | BY3: schv. 2016 ke schv. 2015 | BZ3: PROSTŘEDKY NA PLATY A OPPP v Kč | CA3: z toho : | CC3: POČET ZAMĚSTANCŮ | CD3: Ø měsíční plat v Kč | CE3: Pořadí Ø měsíčního platu | CF3: PROSTŘEDKY NA PLATY A OPPP v Kč | CG3: z toho : | CI3: POČET ZAMĚSTANCŮ | CJ3: Ø měsíční plat v Kč | CK3: Pořadí Ø měsíčního platu | CL3: skut. 2016 k uprav. rozp. 2016 | CM3: skut. 2016 ke skut. 2015 | CO3: PROSTŘEDKY NA PLATY A OPPP v Kč | CP3: z toho : | CR3: POČET ZAMĚSTANCŮ | CS3: Ø měsíční plat v Kč | CT3: Pořadí Ø měsíčního platu | CU3: schv. 2017 ke schv. 2016 | CV3: PROSTŘEDKY NA PLATY A OPPP v Kč | CW3: z toho : | CY3: POČET ZAMĚSTANCŮ | CZ3: Ø měsíční plat v Kč | DA3: Pořadí Ø měsíčního platu | DB3: PROSTŘEDKY NA PLATY A OPPP v Kč | DC3: z toho : | DE3: POČET ZAMĚSTANCŮ | DF3: Ø měsíční plat v Kč | DG3: Pořadí Ø měsíčního platu | DH3: skut. 2017 k uprav. rozp. 2017 | DI3: skut. 2017 ke skut. 2016 | DK3: PROSTŘEDKY NA PLATY A OPPP v Kč | DL3: z toho : | DN3: POČET ZAMĚSTANCŮ | DO3: Ø měsíční plat v Kč | DP3: Pořadí Ø měsíčního platu | DQ3: schv. 2018 ke schv. 2017 | DR3: PROSTŘEDKY NA PLATY A OPPP v Kč | DS3: z toho : | DU3: POČET ZAMĚSTANCŮ | DV3: Ø měsíční plat v Kč | DW3: Pořadí Ø měsíčního platu | DX3: PROSTŘEDKY NA PLATY A OPPP v Kč | DY3: z toho : | EA3: POČET ZAMĚSTANCŮ | EB3: Ø měsíční plat v Kč | EC3: Pořadí Ø měsíčního platu | ED3: skut. 2018 k uprav. rozp. 2018 | EE3: skut. 2018 ke skut. 2017 | EG3: PROSTŘEDKY NA PLATY A OPPP v Kč | EH3: z toho : | EJ3: POČET ZAMĚSTANCŮ | EK3: Ø měsíční plat v Kč | EL3: Pořadí Ø měsíčního platu | EM3: schv. 2019 ke schv. 2018 | EN3: PROSTŘEDKY NA PLATY A OPPP v Kč | EO3: z toho : | EQ3: POČET ZAMĚSTANCŮ | ER3: Ø měsíční plat v Kč | ES3: Pořadí Ø měsíčního platu | ET3: PROSTŘEDKY NA PLATY A OPPP v Kč | EU3: z toho : | EW3: POČET ZAMĚSTANCŮ | EX3: Ø měsíční plat v Kč | EY3: Pořadí Ø měsíčního platu | EZ3: skut. 2019 k uprav. rozp. 2019 | FA3: skut. 2019 ke skut. 2018 | FC3: PROSTŘEDKY NA PLATY A OPPP v Kč | FD3: z toho : | FF3: POČET ZAMĚSTANCŮ | FG3: Ø měsíční plat v Kč | FH3: Pořadí Ø měsíčního platu | FI3: schv. 2020 ke schv. 2019 | FJ3: PROSTŘEDKY NA PLATY A OPPP v Kč | FK3: z toho : | FM3: POČET ZAMĚSTANCŮ | FN3: Ø měsíční plat v Kč | FO3: Pořadí Ø měsíčního platu | FP3: PROSTŘEDKY NA PLATY A OPPP v Kč | FQ3: z toho : | FS3: POČET ZAMĚSTANCŮ | FT3: Ø měsíční plat v Kč | FU3: Pořadí Ø měsíčního platu | FV3: skut. 2020 k uprav. rozp. 2020 | FW3: skut. 2020 ke skut. 2019 | FY3: PROSTŘEDKY NA PLATY A OPPP v Kč | FZ3: z toho : | GB3: POČET ZAMĚSTANCŮ | GC3: Ø měsíční plat v Kč | GD3: Pořadí Ø měsíčního platu | GE3: schv. 2017 ke schv. 2016 | GF3: PROSTŘEDKY NA PLATY A OPPP v Kč | GG3: z toho : | GI3: POČET ZAMĚSTANCŮ | GJ3: Ø měsíční plat v Kč | GK3: Pořadí Ø měsíčního platu | GL3: PROSTŘEDKY NA PLATY A OPPP v Kč | GM3: z toho : | GO3: POČET ZAMĚSTANCŮ | GP3: Ø měsíční plat v Kč | GQ3: Pořadí Ø měsíčního platu | GR3: skut. 2017 k uprav. rozp. 2017 | GS3: skut. 2017 ke skut. 2016 | GU3: PROSTŘEDKY NA PLATY A OPPP v Kč | GV3: z toho : | GX3: POČET ZAMĚSTANCŮ | GY3: Ø měsíční plat v Kč | GZ3: Pořadí Ø měsíčního platu | HA3: schv. 2017 ke schv. 2016 | HB3: PROSTŘEDKY NA PLATY A OPPP v Kč | HC3: z toho : | HE3: POČET ZAMĚSTANCŮ | HF3: Ø měsíční plat v Kč | HG3: Pořadí Ø měsíčního platu | HH3: PROSTŘEDKY NA PLATY A OPPP v Kč | HI3: z toho : | HK3: POČET ZAMĚSTANCŮ | HL3: Ø měsíční plat v Kč | HM3: Pořadí Ø měsíčního platu | HN3: skut. 2017 k uprav. rozp. 2017 | HO3: skut. 2017 ke skut. 2016
C4: kapitola | F4: OPPP v Kč | G4: PROSTŘEDKY NA PLATY | M4: OPPP v Kč | N4: PROSTŘEDKY NA PLATY | S4: OPPP v Kč | T4: PROSTŘEDKY NA PLATY | AB4: OPPP v Kč | AC4: PROSTŘEDKY NA PLATY | AI4: OPPP v Kč | AJ4: PROSTŘEDKY NA PLATY | AO4: OPPP v Kč | AP4: PROSTŘEDKY NA PLATY | AX4: OPPP v Kč | AY4: PROSTŘEDKY NA PLATY | BE4: OPPP v Kč | BF4: PROSTŘEDKY NA PLATY | BK4: OPPP v Kč | BL4: PROSTŘEDKY NA PLATY | BT4: OPPP v Kč | BU4: PROSTŘEDKY NA PLATY | CA4: OPPP v Kč | CB4: PROSTŘEDKY NA PLATY | CG4: OPPP v Kč | CH4: PROSTŘEDKY NA PLATY | CP4: OPPP v Kč | CQ4: PROSTŘEDKY NA PLATY | CW4: OPPP v Kč | CX4: PROSTŘEDKY NA PLATY | DC4: OPPP v Kč | DD4: PROSTŘEDKY NA PLATY | DL4: OPPP v Kč | DM4: PROSTŘEDKY NA PLATY | DS4: OPPP v Kč | DT4: PROSTŘEDKY NA PLATY | DY4: OPPP v Kč | DZ4: PROSTŘEDKY NA PLATY | EH4: OPPP v Kč | EI4: PROSTŘEDKY NA PLATY | EO4: OPPP v Kč | EP4: PROSTŘEDKY NA PLATY | EU4: OPPP v Kč | EV4: PROSTŘEDKY NA PLATY | FD4: OPPP v Kč | FE4: PROSTŘEDKY NA PLATY | FK4: OPPP v Kč | FL4: PROSTŘEDKY NA PLATY | FQ4: OPPP v Kč | FR4: PROSTŘEDKY NA PLATY | FZ4: OPPP v Kč | GA4: PROSTŘEDKY NA PLATY | GG4: OPPP v Kč | GH4: PROSTŘEDKY NA PLATY | GM4: OPPP v Kč | GN4: PROSTŘEDKY NA PLATY | GV4: OPPP v Kč | GW4: PROSTŘEDKY NA PLATY | HC4: OPPP v Kč | HD4: PROSTŘEDKY NA PLATY | HI4: OPPP v Kč | HJ4: PROSTŘEDKY NA PLATY
A6: 301 | B6: KPR | C6: Kancelář prezidenta | E6: 54046000 | F6: 4605000 | G6: 49441000 | H6: 114 | I6: 36141 | J6: 8 | K6: 100 | L6: 54046000 | M6: 4605000 | N6: 49441000 | O6: 114 | P6: 36141 | Q6: 8 | R6: 59985674 | S6: 6948674 | T6: 53037000 | U6: 90 | V6: 49108 | W6: 1 | X6: 135.87892 | Y6: 103.69745 | AA6: 55082200 | AB6: 4652380 | AC6: 50429820 | AD6: 114 | AE6: 36864 | AF6: 8 | AG6: 102.0005 | AH6: 55376374 | AI6: 4652380 | AJ6: 50723994 | AK6: 114 | AL6: 37079 | AM6: 8 | AN6: 60862084 | AO6: 5289726 | AP6: 55572358 | AQ6: 96 | AR6: 48240 | AS6: 1 | AT6: 130.1006 | AU6: 98.232467 | AW6: 57774654 | AX6: 4796867 | AY6: 52977787 | AZ6: 110 | BA6: 40135 | BB6: 8 | BC6: 108.87316 | BD6: 58039543 | BE6: 4796867 | BF6: 53242676 | BG6: 110 | BH6: 40335 | BI6: 8 | BJ6: 63837196 | BK6: 5484393 | BL6: 58352803 | BM6: 101 | BN6: 48146 | BO6: 1 | BP6: 119.36532 | BQ6: 99.805141 | BS6: 59808542 | BT6: 5241421 | BU6: 54567121 | BV6: 110 | BW6: 41339 | BX6: 9 | BY6: 102.99988 | BZ6: 60263268 | CA6: 5241421 | CB6: 55021847 | CC6: 110 | CD6: 41683 | CE6: 7 | CF6: 65718796 | CG6: 5245205 | CH6: 60473591 | CI6: 101 | CJ6: 49896 | CK6: 1 | CL6: 119.70348 | CM6: 103.63478 | CO6: 62745698 | CP6: 5450221 | CQ6: 57295477 | CR6: 110 | CS6: 43406 | CT6: 7 | CU6: 105.00012 | CV6: 63605130 | CW6: 5450221 | CX6: 58154909 | CY6: 110 | CZ6: 44057 | DA6: 8 | DB6: 67191916 | DC6: 5266282 | DD6: 61925634 | DE6: 101 | DF6: 51094 | DG6: 5 | DH6: 115.97249 | DI6: 102.40099 | DK6: 68099091 | DL6: 5647021 | DM6: 62452070 | DN6: 110 | DO6: 47312 | DP6: 9 | DQ6: 108.99876 | DR6: 68099091 | DS6: 5647021 | DT6: 62452070 | DU6: 110 | DV6: 47312 | DW6: 10 | DX6: 67058487 | DY6: 4282805 | DZ6: 62775682 | EA6: 99.65 | EB6: 52497 | EC6: 6 | ED6: 110.95916 | EE6: 102.74592 | EG6: 72767815 | EH6: 5908621 | EI6: 66859194 | EJ6: 110 | EK6: 50651 | EL6: 6 | EM6: 107.05741 | EN6: 72767815 | EO6: 5908621 | EP6: 66859194 | EQ6: 110 | ER6: 50651 | ES6: 8 | ET6: 72439019 | EU6: 5128890 | EV6: 67310129 | EW6: 100.34 | EX6: 55902 | EY6: 4 | EZ6: 110.36702 | FA6: 106.48608 | FC6: 75086215 | FD6: 6247021 | FE6: 68839194 | FF6: 110 | FG6: 52151 | FH6: 11 | FI6: 102.96144 | FJ6: 75086215 | FK6: 6247021 | FL6: 68839194 | FM6: 110 | FN6: 52151 | FO6: 10 | FP6: 74888919 | FQ6: 5721591 | FR6: 69167328 | FS6: 99.46 | FT6: 57952 | FU6: 4 | FV6: 111.12347 | FW6: 103.66713 | FY6: 118484304 | FZ6: 6709021 | GA6: 111775283 | GB6: 162 | GC6: 57498 | GD6: =RANK(GC6,GC$6:GC$49,0) -> 4 | GF6: 118484304 | GG6: 6709021 | GH6: 111775283 | GI6: 162 | GJ6: 57498 | GK6: =RANK(GJ6,GJ$6:GJ$49,0) -> 5 | GL6: 117677550 | GM6: 5799886 | GN6: 111877664 | GO6: 147.33 | GP6: 63281 | GQ6: =RANK(GP6,GP$6:GP$49,0) -> 5 | GR6: 115.97249 | GS6: 102.40099 | GU6: 124634668 | GV6: 7270621 | GW6: 117364047 | GX6: 162 | GY6: 60372 | GZ6: =RANK(GY6,GY$6:GY$49,0) -> 5 | HB6: 124634668 | HC6: 7270621 | HD6: 117364047 | HE6: 162 | HF6: 60372 | HG6: =RANK(HF6,HF$6:HF$49,0) -> 5 | HH6: 128324691 | HI6: 6371429 | HJ6: 121953262 | HK6: 151.86 | HL6: 66922 | HM6: =RANK(HL6,HL$6:HL$49,0) -> 6
A7: 302 | B7: Kparl | C7: Parlament | E7: 335421000 | F7: 178759000 | G7: 156662000 | H7: 362 | I7: 36064 | J7: 9 | K7: 100 | L7: 335421000 | M7: 178759000 | N7: 156662000 | O7: 362 | P7: 36064 | Q7: 9 | R7: 345572102 | S7: 176918026 | T7: 168654076 | U7: 345 | V7: 40738 | W7: 8 | X7: 112.96029 | Y7: 107.97244 | AA7: 338684160 | AB7: 178888920 | AC7: 159795240 | AD7: 362 | AE7: 36785 | AF7: 9 | AG7: 101.99922 | AH7: 339616299 | AI7: 178888920 | AJ7: 160727379 | AK7: 362 | AL7: 37000 | AM7: 9 | AN7: 338896154 | AO7: 160172646 | AP7: 178723508 | AQ7: 353 | AR7: 42192 | AS7: 6 | AT7: 114.03243 | AU7: 103.56915 | AW7: 347887868 | AX7: 180946394 | AY7: 166941474 | AZ7: 360 | BA7: 38644 | BB7: 10 | BC7: 105.05369 | BD7: 360622575 | BE7: 192846394 | BF7: 167776181 | BG7: 360 | BH7: 38837 | BI7: 10 | BJ7: 368431657 | BK7: 177659487 | BL7: 190772170 | BM7: 354 | BN7: 44909 | BO7: 4 | BP7: 115.63458 | BQ7: 106.43961 | BS7: 379040833 | BT7: 207091115 | BU7: 171949718 | BV7: 360 | BW7: 39803 | BX7: 10 | BY7: 102.99917 | BZ7: 380473747 | CA7: 207091115 | CB7: 173382632 | CC7: 360 | CD7: 40135 | CE7: 10 | CF7: 380265838 | CG7: 191702295 | CH7: 188563543 | CI7: 355 | CJ7: 44264 | CK7: 6 | CL7: 110.28778 | CM7: 98.563762 | CO7: 407613030 | CP7: 227065826 | CQ7: 180547204 | CR7: 360 | CS7: 41793 | CT7: 12 | CU7: 104.99962 | CV7: 410321238 | CW7: 227065826 | CX7: 183255412 | CY7: 360 | CZ7: 42420 | DA7: 13 | DB7: 403012156 | DC7: 204242119 | DD7: 198770037 | DE7: 353 | DF7: 46924 | DG7: 10 | DH7: 110.61763 | DI7: 106.0094 | DK7: 487422689 | DL7: 290626237 | DM7: 196796452 | DN7: 360 | DO7: 45555 | DP7: 13 | DQ7: 109.00151 | DR7: 487422689 | DS7: 290626237 | DT7: 196796452 | DU7: 360 | DV7: 45555 | DW7: 15 | DX7: 495413607 | DY7: 276653678 | DZ7: 218759929 | EA7: 355.87 | EB7: 51227 | EC7: 10 | ED7: 112.45088 | EE7: 109.17015 | EG7: 468978598 | EH7: 258214359 | EI7: 210764239 | EJ7: 360 | EK7: 48788 | EL7: 10 | EM7: 107.09692 | EN7: 468978598 | EO7: 258214359 | EP7: 210764239 | EQ7: 360 | ER7: 48788 | ES7: 12 | ET7: 470627168 | EU7: 246867207 | EV7: 223759961 | EW7: 353.6 | EX7: 52734 | EY7: 9 | EZ7: 108.08805 | FA7: 102.94181 | FC7: 501166798 | FD7: 283922559 | FE7: 217244239 | FF7: 360 | FG7: 50288 | FH7: 15 | FI7: 103.07453 | FJ7: 501166798 | FK7: 283922559 | FL7: 217244239 | FM7: 360 | FN7: 50288 | FO7: 13 | FP7: 488235422 | FQ7: 267835242 | FR7: 220400180 | FS7: 347.98 | FT7: 52781 | FU7: 15 | FV7: 104.95745 | FW7: 100.08913 | FY7: 552557633 | FZ7: 320950304 | GA7: 231607329 | GB7: 360 | GC7: 53613 | GD7: =RANK(GC7,GC$6:GC$49,0) -> 12 | GF7: 543589023 | GG7: 311981694 | GH7: 231607329 | GI7: 360 | GJ7: 53613 | GK7: =RANK(GJ7,GJ$6:GJ$49,0) -> 14 | GL7: 542209624 | GM7: 295407844 | GN7: 246801780 | GO7: 350.18 | GP7: 58732 | GQ7: =RANK(GP7,GP$6:GP$49,0) -> 10 | GR7: 110.61763 | GS7: 106.0094 | GU7: 608771243 | GV7: 365583548 | GW7: 243187695 | GX7: 360 | GY7: 56293 | GZ7: =RANK(GY7,GY$6:GY$49,0) -> 10 | HB7: 608771243 | HC7: 350583548 | HD7: 258187695 | HE7: 360 | HF7: 59766 | HG7: =RANK(HF7,HF$6:HF$49,0) -> 6 | HH7: 588409387 | HI7: 315948518 | HJ7: 272460869 | HK7: 353.85 | HL7: 64166 | HM7: =RANK(HL7,HL$6:HL$49,0) -> 10
A8: 303 | B8: Ksen | C8: Kancelář Senátu | E8: 158199000 | F8: 71500000 | G8: 86699000 | H8: 216 | I8: 33449 | J8: 15 | K8: 100 | L8: 158199000 | M8: 71500000 | N8: 86699000 | O8: 216 | P8: 33449 | Q8: 16 | R8: 159719480 | S8: 73105351 | T8: 86614129 | U8: 192 | V8: 37593 | W8: 13 | X8: 112.38901 | Y8: 101.4738 | AA8: 170562980 | AB8: 82130000 | AC8: 88432980 | AD8: 216 | AE8: 34118 | AF8: 16 | AG8: 102.00006 | AH8: 171078839 | AI8: 82130000 | AJ8: 88948839 | AK8: 216 | AL8: 34317 | AM8: 16 | AN8: 160779849 | AO8: 71850428 | AP8: 88929421 | AQ8: 190 | AR8: 39004 | AS8: 10 | AT8: 113.65795 | AU8: 103.75336 | AW8: 163918054 | AX8: 72307303 | AY8: 91610751 | AZ8: 213 | BA8: 35841 | BB8: 17 | BC8: 105.05012 | BD8: 164376108 | BE8: 72307303 | BF8: 92068805 | BG8: 213 | BH8: 36021 | BI8: 17 | BJ8: 171511858 | BK8: 79443929 | BL8: 92067929 | BM8: 191 | BN8: 40169 | BO8: 10 | BP8: 111.5155 | BQ8: 102.98687 | BS8: 188714596 | BT8: 94355522 | BU8: 94359074 | BV8: 213 | BW8: 36917 | BX8: 20 | BY8: 103.00215 | BZ8: 189500922 | CA8: 94355522 | CB8: 95145400 | CC8: 213 | CD8: 37224 | CE8: 19 | CF8: 177689439 | CG8: 82583917 | CH8: 95105522 | CI8: 191.44 | CJ8: 41399 | CK8: 14 | CL8: 111.21588 | CM8: 103.06206 | CO8: 187635350 | CP8: 88558322 | CQ8: 99077028 | CR8: 213 | CS8: 38763 | CT8: 21 | CU8: 105.00041 | CV8: 189121505 | CW8: 88558322 | CX8: 100563183 | CY8: 213 | CZ8: 39344 | DA8: 24 | DB8: 193838081 | DC8: 93286022 | DD8: 100552059 | DE8: 191 | DF8: 43871 | DG8: 19 | DH8: 111.5062 | DI8: 105.97116 | DK8: 214825783 | DL8: 106831822 | DM8: 107993961 | DN8: 213 | DO8: 42251 | DP8: 19 | DQ8: 108.99827 | DR8: 214825783 | DS8: 106831822 | DT8: 107993961 | DU8: 213 | DV8: 42251 | DW8: 21 | DX8: 204066509 | DY8: 96083414 | DZ8: 107983095 | EA8: 189.66 | EB8: 47446 | EC8: 19 | ED8: 112.29557 | EE8: 108.14889 | EG8: 218379921 | EH8: 102628322 | EI8: 115751599 | EJ8: 213 | EK8: 45286 | EL8: 17 | EM8: 107.18326 | EN8: 218379921 | EO8: 102628322 | EP8: 115751599 | EQ8: 213 | ER8: 45286 | ES8: 18 | ET8: 227176041 | EU8: 111434216 | EV8: 115741825 | EW8: 191.46 | EX8: 50377 | EY8: 18 | EZ8: 111.24188 | FA8: 106.17755 | FC8: 236171121 | FD8: 116585522 | FE8: 119585599 | FF8: 213 | FG8: 46786 | FH8: 20 | FI8: 103.31228 | FJ8: 236171121 | FK8: 116585522 | FL8: 119585599 | FM8: 213 | FN8: 46786 | FO8: 19 | FP8: 233975968 | FQ8: 114394310 | FR8: 119581658 | FS8: 189.39 | FT8: 52617 | FU8: 16 | FV8: 112.46313 | FW8: 104.44647 | FY8: 269729032 | FZ8: 147988022 | GA8: 121741010 | GB8: 203 | GC8: 49976 | GD8: =RANK(GC8,GC$6:GC$49,0) -> 23 | GF8: 269729032 | GG8: 147988022 | GH8: 121741010 | GI8: 203 | GJ8: 49976 | GK8: =RANK(GJ8,GJ$6:GJ$49,0) -> 24 | GL8: 257044581 | GM8: 129848776 | GN8: 127195805 | GO8: 192.12 | GP8: 55172 | GQ8: =RANK(GP8,GP$6:GP$49,0) -> 20 | GR8: 111.5062 | GS8: 105.97116 | GU8: 285727130 | GV8: 149499069 | GW8: 136228061 | GX8: 203 | GY8: 55923 | GZ8: =RANK(GY8,GY$6:GY$49,0) -> 14 | HB8: 285727130 | HC8: 149499069 | HD8: 136228061 | HE8: 203 | HF8: 55923 | HG8: =RANK(HF8,HF$6:HF$49,0) -> 18 | HH8: 288969406 | HI8: 148353620 | HJ8: 140615786 | HK8: 191.55 | HL8: 61175 | HM8: =RANK(HL8,HL$6:HL$49,0) -> 13
A9: 304 | B9: ÚV | C9: Úřad vlády | E9: 247595000 | F9: 36904000 | G9: 210691000 | H9: 534 | I9: 32879 | J9: 17 | K9: 101.13504 | L9: 264426961 | M9: 45146938 | N9: 219280023 | O9: 534 | P9: 34220 | Q9: 13 | R9: 258697756 | S9: 39539642 | T9: 219158114 | U9: 433 | V9: 42178 | W9: 4 | X9: 123.25541 | Y9: 103.41547 | AA9: 263583620 | AB9: 41780832 | AC9: 221802788 | AD9: 533 | AE9: 34678 | AF9: 14 | AG9: 105.47158 | AH9: 286126349 | AI9: 43753789 | AJ9: 242372560 | AK9: 572 | AL9: 35311 | AM9: 14 | AN9: 307139297 | AO9: 51799948 | AP9: 255339349 | AQ9: 528 | AR9: 40300 | AS9: 9 | AT9: 114.12874 | AU9: 95.547442 | AW9: 318762637 | AX9: 42382535 | AY9: 276380102 | AZ9: 576 | BA9: 39986 | BB9: 9 | BC9: 115.30653 | BD9: 328906443 | BE9: 46904370 | BF9: 282002073 | BG9: 585 | BH9: 40171 | BI9: 9 | BJ9: 331608710 | BK9: 45987896 | BL9: 285620814 | BM9: 555 | BN9: 42886 | BO9: 7 | BP9: 106.75861 | BQ9: 106.41687 | BS9: 404562528 | BT9: 60609197 | BU9: 343953331 | BV9: 692 | BW9: 41420 | BX9: 8 | BY9: 103.58626 | BZ9: 421338237 | CA9: 60173227 | CB9: 361165010 | CC9: 730 | CD9: 41229 | CE9: 8 | CF9: 394668136 | CG9: 69054585 | CH9: 325613551 | CI9: 621 | CJ9: 43695 | CK9: 7 | CL9: 105.98123 | CM9: 101.8864 | CO9: 474196605 | CP9: 76043353 | CQ9: 398153252 | CR9: 768.2 | CS9: 43191 | CT9: 8 | CU9: 104.27571 | CV9: 494377440 | CW9: 91255853 | CX9: 403121587 | CY9: 768.2 | CZ9: 43730 | DA9: 9 | DB9: 442127703 | DC9: 73998098 | DD9: 368129605 | DE9: 673 | DF9: 45583 | DG9: 17 | DH9: 104.23737 | DI9: 104.32086 | DK9: 482777759 | DL9: 76059898 | DM9: 406717861 | DN9: 764.45 | DO9: 44337 | DP9: 14 | DQ9: 102.65333 | DR9: 477870534 | DS9: 94118465 | DT9: 383752069 | DU9: 700 | DV9: 45685 | DW9: 14 | DX9: 426435335 | DY9: 65504509 | DZ9: 360930826 | EA9: 630.01 | EB9: 47741 | EC9: 18 | ED9: 104.50038 | EE9: 104.73422 | EG9: 454444961 | EH9: 68534439 | EI9: 385910522 | EJ9: 637 | EK9: 50485 | EL9: 7 | EM9: 113.86652 | EN9: 429110328 | EO9: 49126939 | EP9: 379983389 | EQ9: 629.83 | ER9: 50276 | ES9: 9 | ET9: 436227165 | EU9: 76852755 | EV9: 359374410 | EW9: 580.93 | EX9: 51552 | EY9: 13 | EZ9: 102.53799 | FA9: 107.98266 | FC9: 384824392 | FD9: 58535863 | FE9: 326288529 | FF9: 500.2 | FG9: 54360 | FH9: 5 | FI9: 107.67555 | FJ9: 325127517 | FK9: 58535863 | FL9: 266591654 | FM9: 510.2 | FN9: 43544 | FO9: 27 | FP9: 388629075 | FQ9: 61373361 | FR9: 327255714 | FS9: 490.08 | FT9: 55647 | FU9: 9 | FV9: 127.79487 | FW9: 107.94344 | FY9: 465704149 | FZ9: 75110024 | GA9: 390594125 | GB9: 589 | GC9: 55262 | GD9: =RANK(GC9,GC$6:GC$49,0) -> 8 | GF9: 517187881 | GG9: 85705212 | GH9: 431482669 | GI9: 583.79 | GJ9: 61592 | GK9: =RANK(GJ9,GJ$6:GJ$49,0) -> 4 | GL9: 512218563 | GM9: 92244335 | GN9: 419974228 | GO9: 549.44 | GP9: 63697 | GQ9: =RANK(GP9,GP$6:GP$49,0) -> 4 | GR9: 104.23737 | GS9: 104.32086 | GU9: 504163458 | GV9: 91738048 | GW9: 412425410 | GX9: 596.5 | GY9: 57617 | GZ9: =RANK(GY9,GY$6:GY$49,0) -> 9 | HB9: 507542726 | HC9: 89538748 | HD9: 418003978 | HE9: 584.25 | HF9: 59621 | HG9: =RANK(HF9,HF$6:HF$49,0) -> 7 | HH9: 518695257 | HI9: 79745871 | HJ9: 438949386 | HK9: 540.19 | HL9: 67715 | HM9: =RANK(HL9,HL$6:HL$49,0) -> 4
A10: 306 | B10: MZV | C10: Ministerstvo zahraničních věcí | E10: 640341000 | F10: 5231000 | G10: 635110000 | H10: 1772 | I10: 29868 | J10: 23 | K10: 100 | L10: 647644222 | M10: 8140451 | N10: 639503771 | O10: 1780 | P10: 29939 | Q10: 23 | R10: 655906399 | S10: 7020757 | T10: 648885642 | U10: 1721 | V10: 31420 | W10: 23 | X10: 104.94673 | Y10: 101.42682 | AA10: 674197303 | AB10: 6615620 | AC10: 667581683 | AD10: 1824 | AE10: 30500 | AF10: 23 | AG10: 102.11598 | AH10: 678399909 | AI10: 6615620 | AJ10: 671784289 | AK10: 1825 | AL10: 30675 | AM10: 23 | AN10: 677552857 | AO10: 6293325 | AP10: 671259532 | AQ10: 1748 | AR10: 32001 | AS10: 24 | AT10: 104.32274 | AU10: 101.84914 | AW10: 714580096 | AX10: 6898002 | AY10: 707682094 | AZ10: 1845 | BA10: 31964 | BB10: 23 | BC10: 104.8 | BD10: 722406568 | BE10: 6898002 | BF10: 715508566 | BG10: 1855 | BH10: 32143 | BI10: 23 | BJ10: 729716796 | BK10: 9788151 | BL10: 719928645 | BM10: 1778 | BN10: 33742 | BO10: 23 | BP10: 104.97464 | BQ10: 105.44045 | BS10: 760719268 | BT10: 7276958 | BU10: 753442310 | BV10: 1951 | BW10: 32182 | BX10: 25 | BY10: 100.68202 | BZ10: 771107283 | CA10: 7276958 | CB10: 763830325 | CC10: 1973 | CD10: 32262 | CE10: 27 | CF10: 768808680 | CG10: 6864995 | CH10: 761943685 | CI10: 1795 | CJ10: 35373 | CK10: 24 | CL10: 109.64292 | CM10: 104.83374 | CO10: 826811296 | CP10: 7395758 | CQ10: 819415538 | CR10: 2000 | CS10: 34142 | CT10: 25 | CU10: 106.09036 | CV10: 843625280 | CW10: 8495758 | CX10: 835129522 | CY10: 2004.83 | CZ10: 34713 | DA10: 30 | DB10: 8.3780593e+08 | DC10: 6438096.4 | DD10: 831367837 | DE10: 1818 | DF10: 38108 | DG10: 28 | DH10: 109.7802 | DI10: 107.73189 | DK10: 908282421 | DL10: 7508558 | DM10: 900773863 | DN10: 2020.5 | DO10: 37151 | DP10: 29 | DQ10: 108.81319 | DR10: 909986671 | DS10: 9108558 | DT10: 900878113 | DU10: 2026.17 | DV10: 37052 | DW10: 31 | DX10: 8.9418463e+08 | DY10: 6724311.8 | DZ10: 887460314 | EA10: 1807.47 | EB10: 40916 | EC10: 30 | ED10: 110.42859 | EE10: 107.36853 | EG10: 944305498 | EH10: 7846958 | EI10: 936458540 | EJ10: 2032.5 | EK10: 38395 | EL10: 33 | EM10: 103.3485 | EN10: 965543162 | EO10: 7846958 | EP10: 957696204 | EQ10: 2040 | ER10: 39122 | ES10: 29 | ET10: 963133811 | EU10: 10653624 | EV10: 952480187 | EW10: 1847.69 | EX10: 42958 | EY10: 30 | EZ10: 109.80522 | FA10: 104.99071 | FC10: 995622788 | FD10: 8172386 | FE10: 987450402 | FF10: 2048.58 | FG10: 40168 | FH10: 34 | FI10: 104.61779 | FJ10: 1015229954 | FK10: 8172386 | FL10: 1007057568 | FM10: 2072.57 | FN10: 40491 | FO10: 35 | FP10: 1017067313 | FQ10: 8815528 | FR10: 1008251785 | FS10: 1867.31 | FT10: 44996 | FU10: 31 | FV10: 111.12593 | FW10: 104.74417 | FY10: 1122206154 | FZ10: 8116958 | GA10: 1114089196 | GB10: 2062 | GC10: 45025 | GD10: =RANK(GC10,GC$6:GC$49,0) -> 32 | GF10: 1118200234 | GG10: 8116958 | GH10: 1110083276 | GI10: 2055.66 | GJ10: 45001 | GK10: =RANK(GJ10,GJ$6:GJ$49,0) -> 35 | GL10: 1105220054 | GM10: 8878190 | GN10: 1096341864 | GO10: 1865.28 | GP10: 48980 | GQ10: =RANK(GP10,GP$6:GP$49,0) -> 31 | GR10: 109.7802 | GS10: 107.73189 | GU10: 1171214258 | GV10: 8437358 | GW10: 1162776900 | GX10: 2052 | GY10: 47221 | GZ10: =RANK(GY10,GY$6:GY$49,0) -> 36 | HB10: 1167180539 | HC10: 10900854 | HD10: 1156279685 | HE10: 2051.75 | HF10: 46963 | HG10: =RANK(HF10,HF$6:HF$49,0) -> 36 | HH10: 1.1531265e+09 | HI10: 7978309.4 | HJ10: 1145148198 | HK10: 1872.15 | HL10: 50973 | HM10: =RANK(HL10,HL$6:HL$49,0) -> 36
A11: 307 | B11: MO | C11: Ministerstvo obrany | E11: 10227092000 | F11: 1038841000 | G11: 9188251000 | H11: 31734 | I11: 24128 | J11: 34 | K11: 100 | L11: 10437326921 | M11: 1419808963 | N11: 9017517958 | O11: 30960 | P11: 24272 | Q11: 34 | R11: 10428247209 | S11: 1473039251 | T11: 8955207958 | U11: 29817 | V11: 25028 | W11: 36 | X11: 103.1147 | Y11: 100.65149 | AA11: 10418018514 | AB11: 1039217000 | AC11: 9378801514 | AD11: 29290 | AE11: 26684 | AF11: 32 | AG11: 110.5935 | AH11: 10648875354 | AI11: 1381710110 | AJ11: 9267165244 | AK11: 28873 | AL11: 26747 | AM11: 33 | AN11: 10656817436 | AO11: 1377297742 | AP11: 9279519694 | AQ11: 28433 | AR11: 27197 | AS11: 35 | AT11: 101.68243 | AU11: 108.66629 | AW11: 10856582569 | AX11: 1090369391 | AY11: 9766213178 | AZ11: 29290 | BA11: 27786 | BB11: 34 | BC11: 104.12982 | BD11: 11140424642 | BE11: 1100374657 | BF11: 10040049985 | BG11: 29503 | BH11: 28359 | BI11: 34 | BJ11: 1.1137853e+10 | BK11: 1.0921154e+09 | BL11: 1.0045738e+10 | BM11: 28933 | BN11: 28934 | BO11: 35 | BP11: 102.02758 | BQ11: 106.38673 | BS11: 11924615531 | BT11: 759611900 | BU11: 11165003631 | BV11: 30552 | BW11: 30454 | BX11: 33 | BY11: 109.60196 | BZ11: 12375117353 | CA11: 946779420 | CB11: 11428337933 | CC11: 30757 | CD11: 30964 | CE11: 33 | CF11: 1.23813e+10 | CG11: 939873320 | CH11: 1.1441426e+10 | CI11: 30332 | CJ11: 31434 | CK11: 34 | CL11: 101.51789 | CM11: 108.64035 | CO11: 13460507641 | CP11: 831800807 | CQ11: 12628706834 | CR11: 32516 | CS11: 32365 | CT11: 33 | CU11: 106.27504 | CV11: 13361424815 | CW11: 939788179 | CX11: 12421636636 | CY11: 31462 | CZ11: 32901 | DA11: 36 | DB11: 1.3278346e+10 | DC11: 922155567 | DD11: 1.2356191e+10 | DE11: 30567 | DF11: 33686 | DG11: 37 | DH11: 102.38595 | DI11: 107.16422 | DK11: 15458894814 | DL11: 1157008259 | DM11: 14301886555 | DN11: 32557 | DO11: 36607 | DP11: 32 | DQ11: 113.10675 | DR11: 15469585459 | DS11: 1161690404 | DT11: 14307895055 | DU11: 32557 | DV11: 36623 | DW11: 33 | DX11: 1.5475964e+10 | DY11: 1.1087063e+09 | DZ11: 14367257512 | EA11: 31622.59 | EB11: 37861 | EC11: 37 | ED11: 103.38039 | EE11: 112.39387 | EG11: 17314001889 | EH11: 1767733171 | EI11: 15546268718 | EJ11: 33622 | EK11: 38532 | EL11: 31 | EM11: 105.25856 | EN11: 17324283786 | EO11: 1772130508 | EP11: 15552153278 | EQ11: 33622 | ER11: 38547 | ES11: 35 | ET11: 1.7241735e+10 | EU11: 1.7312578e+09 | EV11: 1.5510477e+10 | EW11: 32551.02 | EX11: 39708 | EY11: 38 | EZ11: 103.01191 | FA11: 104.87837 | FC11: 17917157923 | FD11: 1744137395 | FE11: 16173020528 | FF11: 34657 | FG11: 38888 | FH11: 38 | FI11: 100.92391 | FJ11: 17892879005 | FK11: 1682345032 | FL11: 16210533973 | FM11: 33830 | FN11: 39931 | FO11: 38 | FP11: 17743857921 | FQ11: 1549446622 | FR11: 16194411299 | FS11: 33483.48 | FT11: 40304 | FU11: 39 | FV11: 100.93411 | FW11: 101.50096 | FY11: 21492526025 | FZ11: 1470504849 | GA11: 20022021176 | GB11: 37619 | GC11: 44353 | GD11: =RANK(GC11,GC$6:GC$49,0) -> 34 | GF11: 21999777531 | GG11: 1555624788 | GH11: 20444152743 | GI11: 37619 | GJ11: 45288 | GK11: =RANK(GJ11,GJ$6:GJ$49,0) -> 34 | GL11: 2.1174916e+10 | GM11: 1.5060771e+09 | GN11: 19668838968 | GO11: 35466.42 | GP11: 46215 | GQ11: =RANK(GP11,GP$6:GP$49,0) -> 37 | GR11: 102.38595 | GS11: 107.16422 | GU11: 23518816507 | GV11: 1466187557 | GW11: 22052628950 | GX11: 38809 | GY11: 47353 | GZ11: =RANK(GY11,GY$6:GY$49,0) -> 35 | HB11: 22900575570 | HC11: 1470811707 | HD11: 21429763863 | HE11: 38809 | HF11: 46015 | HG11: =RANK(HF11,HF$6:HF$49,0) -> 38 | HH11: 2.2988024e+10 | HI11: 1.5062708e+09 | HJ11: 2.1481754e+10 | HK11: 36118.04 | HL11: 49564 | HM11: =RANK(HL11,HL$6:HL$49,0) -> 38
A12: 308 | B12: NBÚ | C12: Národní bezpečnostní úřad | E12: 130608000 | F12: 1812000 | G12: 128796000 | H12: 294 | I12: 36507 | J12: 6 | K12: 101.70214 | L12: 131788000 | M12: 1812000 | N12: 129976000 | O12: 296 | P12: 36592 | Q12: 6 | R12: 129440136 | S12: 1231226 | T12: 128208910 | U12: 279 | V12: 38294 | W12: 11 | X12: 104.65129 | Y12: 101.22386 | AA12: 143749898 | AB12: 1848240 | AC12: 141901658 | AD12: 310 | AE12: 38146 | AF12: 5 | AG12: 104.48955 | AH12: 144577658 | AI12: 1848240 | AJ12: 142729418 | AK12: 310 | AL12: 38368 | AM12: 5 | AN12: 142096196 | AO12: 1351736 | AP12: 140744460 | AQ12: 290 | AR12: 40444 | AS12: 8 | AT12: 105.41076 | AU12: 105.61446 | AW12: 155078393 | AX12: 1941622 | AY12: 153136771 | AZ12: 316 | BA12: 40384 | BB12: 7 | BC12: 105.86693 | BD12: 155844077 | BE12: 1941622 | BF12: 153902455 | BG12: 316 | BH12: 40586 | BI12: 7 | BJ12: 151481114 | BK12: 1562290 | BL12: 149918824 | BM12: 303 | BN12: 41232 | BO12: 9 | BP12: 101.59168 | BQ12: 101.94837 | BS12: 164916377 | BT12: 1999871 | BU12: 162916506 | BV12: 324 | BW12: 41902 | BX12: 6 | BY12: 103.75891 | BZ12: 166317228 | CA12: 1999871 | CB12: 164317357 | CC12: 333 | CD12: 41120 | CE12: 9 | CF12: 165647889 | CG12: 2521929 | CH12: 163125960 | CI12: 312 | CJ12: 43570 | CK12: 9 | CL12: 105.95817 | CM12: 105.67035 | CO12: 187547263 | CP12: 1999871 | CQ12: 185547392 | CR12: 352 | CS12: 43927 | CT12: 6 | CU12: 104.8327 | CV12: 164462070 | CW12: 1577407 | CX12: 162884663 | CY12: 330.91 | CZ12: 41019 | DA12: 18 | DB12: 167504390 | DC12: 1713309 | DD12: 165791081 | DE12: 295 | DF12: 46834 | DG12: 12 | DH12: 114.17636 | DI12: 107.49139 | DK12: 154889377 | DL12: 1420438 | DM12: 153468939 | DN12: 268 | DO12: 47720 | DP12: 8 | DQ12: 108.63478 | DR12: 154889377 | DS12: 1420438 | DT12: 153468939 | DU12: 268 | DV12: 47720 | DW12: 8 | DX12: 156122766 | DY12: 1295413 | DZ12: 154827353 | EA12: 249.67 | EB12: 51677 | EC12: 8 | ED12: 108.29212 | EE12: 110.34078 | EG12: 158091571 | EH12: 1420438 | EI12: 156671133 | EJ12: 268 | EK12: 48716 | EL12: 11 | EM12: 102.08718 | EN12: 161091571 | EO12: 2260438 | EP12: 158831133 | EQ12: 268 | ER12: 49388 | ES12: 10 | ET12: 160848569 | EU12: 3489188 | EV12: 157359381 | EW12: 254.44 | EX12: 51538 | EY12: 14 | EZ12: 104.35328 | FA12: 99.731022 | FC12: 166149005 | FD12: 1420438 | FE12: 164728567 | FF12: 262 | FG12: 52395 | FH12: 10 | FI12: 107.55193 | FJ12: 166149005 | FK12: 1420438 | FL12: 164728567 | FM12: 262 | FN12: 52395 | FO12: 9 | FP12: 161387122 | FQ12: 1260714 | FR12: 160126408 | FS12: 245.64 | FT12: 54323 | FU12: 11 | FV12: 103.67974 | FW12: 105.40378 | FY12: 169118073 | FZ12: 1420438 | GA12: 167697635 | GB12: 262 | GC12: 53339 | GD12: =RANK(GC12,GC$6:GC$49,0) -> 13 | GF12: 171118073 | GG12: 1420438 | GH12: 169697635 | GI12: 262 | GJ12: 53975 | GK12: =RANK(GJ12,GJ$6:GJ$49,0) -> 12 | GL12: 163305774 | GM12: 1287300 | GN12: 162018474 | GO12: 235.18 | GP12: 57409 | GQ12: =RANK(GP12,GP$6:GP$49,0) -> 13 | GR12: 114.17636 | GS12: 107.49139 | GU12: 177502955 | GV12: 1420438 | GW12: 176082517 | GX12: 262 | GY12: 56006 | GZ12: =RANK(GY12,GY$6:GY$49,0) -> 12 | HB12: 184411290 | HC12: 1420438 | HD12: 182990852 | HE12: 262 | HF12: 58203 | HG12: =RANK(HF12,HF$6:HF$49,0) -> 9 | HH12: 182091638 | HI12: 2626566 | HJ12: 179465072 | HK12: 232.85 | HL12: 64228 | HM12: =RANK(HL12,HL$6:HL$49,0) -> 9
A13: 309 | B13: KVOP | C13: kancelář veřejného ochránce práv | E13: 48080000 | F13: 5639000 | G13: 42441000 | H13: 113 | I13: 31299 | J13: 19 | K13: 100 | L13: 50334000 | M13: 5639000 | N13: 44695000 | O13: 118 | P13: 31564 | Q13: 20 | R13: 49843209 | S13: 5639000 | T13: 44204209 | U13: 115 | V13: 32032 | W13: 21 | X13: 101.4827 | Y13: 99.626773 | AA13: 50848480 | AB13: 5259580 | AC13: 45588900 | AD13: 119 | AE13: 31925 | AF13: 21 | AG13: 102.00006 | AH13: 53554365 | AI13: 5504580 | AJ13: 48049785 | AK13: 122 | AL13: 32821 | AM13: 20 | AN13: 54799701 | AO13: 5389557 | AP13: 49410144 | AQ13: 123 | AR13: 33476 | AS13: 22 | AT13: 101.99567 | AU13: 104.50799 | AW13: 59497817 | AX13: 5716395 | AY13: 53781422 | AZ13: 133 | BA13: 33698 | BB13: 22 | BC13: 105.55364 | BD13: 59261839 | BE13: 5708995 | BF13: 53552844 | BG13: 130 | BH13: 34329 | BI13: 22 | BJ13: 60995724 | BK13: 6049151 | BL13: 54946573 | BM13: 132 | BN13: 34688 | BO13: 21 | BP13: 101.04576 | BQ13: 103.6205 | BS13: 58603536 | BT13: 5953580 | BU13: 52649956 | BV13: 127 | BW13: 34547 | BX13: 22 | BY13: 102.51944 | BZ13: 59371636 | CA13: 6001680 | CB13: 53369956 | CC13: 128 | CD13: 34746 | CE13: 22 | CF13: 63676375 | CG13: 7061549 | CH13: 56614826 | CI13: 132 | CJ13: 35742 | CK13: 22 | CL13: 102.86652 | CM13: 103.03851 | CO13: 64761787 | CP13: 6257580 | CQ13: 58504207 | CR13: 133 | CS13: 36657 | CT13: 22 | CU13: 106.10762 | CV13: 67034870 | CW13: 6523032 | CX13: 60511838 | CY13: 136 | CZ13: 37078 | DA13: 25 | DB13: 68695406 | DC13: 7382214 | DD13: 61313192 | DE13: 137 | DF13: 37295 | DG13: 30 | DH13: 100.58525 | DI13: 104.34503 | DK13: 77344724 | DL13: 6689580 | DM13: 70655144 | DN13: 149.25 | DO13: 39450 | DP13: 26 | DQ13: 107.61928 | DR13: 81319400 | DS13: 6802980 | DT13: 74516420 | DU13: 156.25 | DV13: 39742 | DW13: 26 | DX13: 81675188 | DY13: 7332966 | DZ13: 74342222 | EA13: 157.39 | EB13: 39362 | EC13: 34 | ED13: 99.043833 | EE13: 105.5423 | EG13: 86112638 | EH13: 7003880 | EI13: 79108758 | EJ13: 155.67 | EK13: 42349 | EL13: 23 | EM13: 107.34854 | EN13: 93283838 | EO13: 8455080 | EP13: 84828758 | EQ13: 164.67 | ER13: 42929 | ES13: 23 | ET13: 89259665 | EU13: 9099342 | EV13: 80160323 | EW13: 156.24 | EX13: 42755 | EY13: 32 | EZ13: 99.59468 | FA13: 108.61999 | FC13: 88773338 | FD13: 7444580 | FE13: 81328758 | FF13: 154 | FG13: 44009 | FH13: 26 | FI13: 103.91981 | FJ13: 88773338 | FK13: 7444580 | FL13: 81328758 | FM13: 154 | FN13: 44009 | FO13: 26 | FP13: 96062386 | FQ13: 10248671 | FR13: 85813715 | FS13: 162.41 | FT13: 44031 | FU13: 32 | FV13: 100.04999 | FW13: 102.98445 | FY13: 91264225 | FZ13: 7993580 | GA13: 83270645 | GB13: 154 | GC13: 45060 | GD13: =RANK(GC13,GC$6:GC$49,0) -> 31 | GF13: 94264225 | GG13: 7993580 | GH13: 86270645 | GI13: 154 | GJ13: 46683 | GK13: =RANK(GJ13,GJ$6:GJ$49,0) -> 30 | GL13: 95891502 | GM13: 9088750 | GN13: 86802752 | GO13: 153.11 | GP13: 47244 | GQ13: =RANK(GP13,GP$6:GP$49,0) -> 36 | GR13: 100.58525 | GS13: 104.34503 | GU13: 107206357 | GV13: 12010580 | GW13: 95195777 | GX13: 154 | GY13: 51513 | GZ13: =RANK(GY13,GY$6:GY$49,0) -> 27 | HB13: 110204414 | HC13: 12010580 | HD13: 98193834 | HE13: 158.85 | HF13: 51513 | HG13: =RANK(HF13,HF$6:HF$49,0) -> 27 | HH13: 1.0715732e+08 | HI13: 9284877 | HJ13: 97872447 | HK13: 156.77 | HL13: 52025 | HM13: =RANK(HL13,HL$6:HL$49,0) -> 33
A14: 312 | B14: MF | C14: Ministerstvo financí | E14: 7821874000 | F14: 57913000 | G14: 7763961000 | H14: 24218 | I14: 26716 | J14: 28 | K14: 102.93596 | L14: 8044437273 | M14: 67876373 | N14: 7976560900 | O14: 24222 | P14: 27443 | Q14: 27 | R14: 7983989972 | S14: 41909093 | T14: 7942080879 | U14: 23347 | V14: 28348 | W14: 33 | X14: 103.29774 | Y14: 102.01893 | AA14: 8199608731 | AB14: 59013120 | AC14: 8140595611 | AD14: 24279 | AE14: 27941 | AF14: 28 | AG14: 104.58527 | AH14: 8275514578 | AI14: 59557495 | AJ14: 8215957083 | AK14: 24305 | AL14: 28170 | AM14: 30 | AN14: 8242061671 | AO14: 54195496 | AP14: 8187866175 | AQ14: 23478 | AR14: 29062 | AS14: 33 | AT14: 103.16649 | AU14: 102.5187 | AW14: 8828251329 | AX14: 58717384 | AY14: 8769533945 | AZ14: 24878 | BA14: 29375 | BB14: 31 | BC14: 105.13224 | BD14: 8921590706 | BE14: 63834652 | BF14: 8857756054 | BG14: 24873 | BH14: 29677 | BI14: 30 | BJ14: 8880924963 | BK14: 40644785 | BL14: 8840280178 | BM14: 23744 | BN14: 31026 | BO14: 30 | BP14: 104.54561 | BQ14: 106.75797 | BS14: 9932195024 | BT14: 65187653 | BU14: 9867007371 | BV14: 25516 | BW14: 32225 | BX14: 24 | BY14: 109.70213 | BZ14: 10013570402 | CA14: 65613387 | CB14: 9947957015 | CC14: 25517 | CD14: 32488 | CE14: 25 | CF14: 9730203585 | CG14: 36420621 | CH14: 9693782964 | CI14: 23767 | CJ14: 33989 | CK14: 27 | CL14: 104.62017 | CM14: 109.55005 | CO14: 11017621431 | CP14: 66733494 | CQ14: 10950887937 | CR14: 26120 | CS14: 34938 | CT14: 23 | CU14: 108.41893 | CV14: 11260189028 | CW14: 68287466 | CX14: 11191901562 | CY14: 26120 | CZ14: 35707 | DA14: 26 | DB14: 1.1200994e+10 | DC14: 36035922 | DD14: 1.1164958e+10 | DE14: 24076 | DF14: 38645 | DG14: 26 | DH14: 108.22808 | DI14: 113.69855 | DK14: 12088147819 | DL14: 51206397 | DM14: 12036941422 | DN14: 26174.67 | DO14: 38322 | DP14: 27 | DQ14: 109.68573 | DR14: 12090038535 | DS14: 53097113 | DT14: 12036941422 | DU14: 26182.67 | DV14: 38311 | DW14: 28 | DX14: 1.2071509e+10 | DY14: 31370344 | DZ14: 1.2040139e+10 | EA14: 24322.18 | EB14: 41252 | EC14: 28 | ED14: 107.67665 | EE14: 106.74602 | EG14: 12518046807 | EH14: 58233400 | EI14: 12459813407 | EJ14: 25831 | EK14: 40197 | EL14: 28 | EM14: 104.89275 | EN14: 12483733368 | EO14: 59354908 | EP14: 12424378460 | EQ14: 25833 | ER14: 40079 | ES14: 28 | ET14: 12432866640 | EU14: 37344943 | EV14: 12395521697 | EW14: 24142.03 | EX14: 42787 | EY14: 31 | EZ14: 106.75666 | FA14: 103.72103 | FC14: 12884107340 | FD14: 53941982 | FE14: 12830165358 | FF14: 24885 | FG14: 42965 | FH14: 28 | FI14: 106.88609 | FJ14: 12921837798 | FK14: 88625376 | FL14: 12833212422 | FM14: 24888.84 | FN14: 42968 | FO14: 29 | FP14: 1.2831916e+10 | FQ14: 102743197 | FR14: 1.2729173e+10 | FS14: 23560.11 | FT14: 45024 | FU14: 30 | FV14: 104.78496 | FW14: 105.22822 | FY14: 13038946442 | FZ14: 57330478 | GA14: 12981615964 | GB14: 23458 | GC14: 46117 | GD14: =RANK(GC14,GC$6:GC$49,0) -> 30 | GF14: 13049114063 | GG14: 58254903 | GH14: 12990859160 | GI14: 23456.87 | GJ14: 46152 | GK14: =RANK(GJ14,GJ$6:GJ$49,0) -> 32 | GL14: 1.273951e+10 | GM14: 76307371 | GN14: 1.2663203e+10 | GO14: 21604.61 | GP14: 48845 | GQ14: =RANK(GP14,GP$6:GP$49,0) -> 32 | GR14: 108.22808 | GS14: 113.69855 | GU14: 13698338262 | GV14: 57080922 | GW14: 13641257340 | GX14: 23308.667 | GY14: 48770 | GZ14: =RANK(GY14,GY$6:GY$49,0) -> 34 | HB14: 13312889256 | HC14: 61477124 | HD14: 13251412132 | HE14: 23323 | HF14: 47347 | HG14: =RANK(HF14,HF$6:HF$49,0) -> 35 | HH14: 1.3228378e+10 | HI14: 47861289 | HJ14: 1.3180517e+10 | HK14: 21323.57 | HL14: 51510 | HM14: =RANK(HL14,HL$6:HL$49,0) -> 34
